Workbook

Sheet 📊 Summary Dashboard
A1: LeKise Trading — CRM & Pipeline Analysis 2026 | Pole Division | อัปเดต 16 มิ.ย. 2569
A3: Pipeline รวม (incl VAT) | C3: ก่อน VAT รวม | E3: 🔥 Hot Deals (≥3M) | G3: 📞 Follow-High (1-3M) | I3: จำนวนใบเสนอราคา | K3: ลูกค้าไม่ซ้ำ | M3: 📋 ติดตาม (0.3-1M) | O3: ⚪ รอผล (<0.3M)
A4: ฿ 183.8M | C4: ฿ 171.8M | E4: ฿ 62.0M | G4: ฿ 49.3M | I4: 311 ใบ | K4: 273 ราย | M4: ฿ 55.0M | O4: ฿ 17.6M
A6: 📅 Pipeline รายเดือน (incl VAT)
A7: เดือน | B7: ใบเสนอ | C7: ก่อน VAT | D7: VAT 7% | E7: รวม incl VAT | F7: % Pipeline | G7: สถานะ
A8: 2026-01 | B8: 58 | C8: 49030066 | D8: 3432104.6 | E8: 52462171 | F8: 28.5% | G8: 🔥
A9: 2026-02 | B9: 56 | C9: 19978372 | D9: 1398486 | E9: 21376858 | F9: 11.6% | G9: 🔥
A10: 2026-03 | B10: 54 | C10: 18459011 | D10: 1292130.8 | E10: 19751142 | F10: 10.7% | G10: 🔥
A11: 2026-04 | B11: 47 | C11: 17954717 | D11: 1256830.2 | E11: 19211547 | F11: 10.5% | G11: 🔥
A12: 2026-05 | B12: 65 | C12: 37399847 | D12: 2617989.3 | E12: 40017836 | F12: 21.8% | G12: 🔥
A13: 2026-06 | B13: 31 | C13: 28993372 | D13: 2029536 | E13: 31022908 | F13: 16.9% | G13: 🔥
A14: รวมทั้งหมด | C14: 1.7184668e+08 | D14: 11995777 | E14: 1.8384246e+08 | F14: 100%
A16: 📦 Pipeline by กลุ่มสินค้า
A17: กลุ่มสินค้า | B17: ใบเสนอ | C17: มูลค่า (incl VAT) | D17: % Pipeline
A18: High Mast | B18: 74 | C18: 77140277 | D18: 42.0%
A19: Guard Rail / การ์ดเรล | B19: 21 | C19: 17260953 | D19: 9.4%
A20: เสาไฟถนน | B20: 133 | C20: 61747862 | D20: 33.6%
A21: LED Streetlight | B21: 15 | C21: 4571903.6 | D21: 2.5%
A22: LED Floodlight | B22: 4 | C22: 3151514.9 | D22: 1.7%
A23: LED Highbay | B23: 2 | C23: 266470.23 | D23: 0.1%
A24: Solar | B24: 3 | C24: 675355.92 | D24: 0.4%
A25: สายส่งไฟฟ้า | B25: 1 | C25: 2615208.4 | D25: 1.4%
A26: Hardware / Accessories | B26: 3 | C26: 120572.31 | D26: 0.1%
A27: Electrical Accessories | B27: 3 | C27: 96098.89 | D27: 0.1%
A28: อื่นๆ | B28: 52 | C28: 16196245 | D28: 8.8%
A30: 🏆 Top 20 ลูกค้า (Pipeline incl VAT)
A31: # | B31: ชื่อลูกค้า | C31: ใบเสนอ | D31: มูลค่า (฿) | E31: % Pipeline
A32: 1 | B32: กรรณเลิศ เทรดดิ้ง | C32: 3 | D32: 9826598.3 | E32: 5.3%
A33: 2 | B33: ภิรมย์ กรุ๊ป | C33: 1 | D33: 9536178.1 | E33: 5.2%
A34: 3 | B34: สุรัตน์ | C34: 1 | D34: 7387488.7 | E34: 4.0%
A35: 4 | B35: ห้างหุ้นส่วนจำกัด สมบูรณ์อิเล็กทริค หนองบัวลำภู | C35: 1 | D35: 6855170.1 | E35: 3.7%
A36: 5 | B36: ต้นตะวัน | C36: 1 | D36: 5807540 | E36: 3.2%
A37: 6 | B37: วันชัยการไฟฟ้า HM20_8 | C37: 1 | D37: 4709493.3 | E37: 2.6%
A38: 7 | B38: วันชัยการไฟฟ้า | C38: 1 | D38: 4425301.7 | E38: 2.4%
A39: 8 | B39: เบตเตอร์ เวิร์ลด | C39: 1 | D39: 3838838.6 | E39: 2.1%
A40: 9 | B40: เทศบาลนครเชียงใหม่ | C40: 1 | D40: 3805428.2 | E40: 2.1%
A41: 10 | B41: วันชัยการไฟฟ้า 2019 | C41: 1 | D41: 3578683 | E41: 1.9%
A42: 11 | B42: บริษัท เดอะวิน เทเลคอม จำกัด | C42: 1 | D42: 3257133.5 | E42: 1.8%
A43: 12 | B43: เค บี เอ็ม _25ม. 15 | C43: 1 | D43: 2747332 | E43: 1.5%
... A51: 20 | B51: หจก.ชนก อิเล็คทริค | C51: 1 | D51: 2110831.8 | E51: 1.1%

Sheet 📋 CRM Table
A1: LeKise CRM | ใบเสนอราคา 2026 | 311 รายการ | อัปเดต 16 มิ.ย. 2569 | ตัด Revision ซ้ำ (รวม PL857)
A3: Pipeline: 183.8M ฿ | F3: Hot≥3M: 62.0M ฿ | K3: 311 ใบ (ทบทวนแล้ว) | O3: EGAT:2.3M | DOA:3.1M | APT:5.8M
A4: PL No. | B4: เดือน | C4: ชื่อลูกค้า | D4: ประเภท | E4: เลขที่ใบเสนอ | F4: วันที่ | G4: กลุ่มสินค้า | H4: สินค้าหลัก | I4: ก่อน VAT (฿) | J4: VAT 7% (฿) | K4: รวม incl VAT (฿) | L4: สถานะ (Auto) | M4: ความสำคัญ | N4: จำนวน | O4: กลุ่มงาน | P4: ★ สถานะตามจริง | Q4: หมายเหตุ / ผลติดต่อ | R4: วันติดตาม | S4: Action
A5: PL34 | B5: 2026-04 | D5: B2B อื่นๆ | E5: LKT. 2026-04 -PL819 | F5: 17 เมษายน 2026 | G5: LED Streetlight | H5: กิ่ง (ทอกลมหนา 2.3mm.) ขนาด 2x2.4 ม. R300 ตัด 2 ทาง | I5: 711088 | J5: 49776.16 | K5: 760864.16 | L5: 📋 ติดตาม | M5: กลาง | N5: 1 | O5: —
A6: PL607 | B6: 2026-01 | C6: อินเตอร์ เอ็กซ์เพิร์ท | D6: B2B อื่นๆ | E6: LKT. 2026-01 -PL607 | F6: 5 มกราคม 2025 | G6: High Mast | H6: High Mast 15 M PCD550 M32 8 Hole + วงแหวน 6 โคม REV.3 | I6: 1068540.6 | J6: 74797.84 | K6: 1143338.4 | L6: 📞 ติดตาม-High | M6: สูง | N6: 1 | O6: —
A7: PL608 | B7: 2026-01 | C7: คุณมานพ รัตนภาค | D7: B2C บุคคล | E7: LKT. 2026-01-PL608 | F7: 5 มกราคม 2026 | G7: อื่นๆ | H7: อื่นๆ | I7: 476828.8 | J7: 33378.02 | K7: 510206.82 | L7: 📋 ติดตาม | M7: กลาง | N7: 0 | O7: —
A8: PL609 | B8: 2026-01 | C8: PT ชาติดกิติออย | D8: B2B อื่นๆ | E8: LKT. 2026-01 -PL609 | F8: 6 มกราคม 2026 | G8: LED Streetlight | H8: LED Streetlight 150W 5700K 19,500lm CRI70 140D | I8: 203000 | J8: 14210 | K8: 217210 | L8: ⚪ รอผล | M8: ต่ำ | N8: 1 | O8: —
A9: PL610 | B9: 2026-01 | C9: ที เค | D9: B2B อื่นๆ | E9: LKT. 2026-01 -PL610 | F9: 6 มกราคม 2026 | G9: เสาไฟถนน | H9: Pole With Bracket 9M-T4-TR | I9: 1881012 | J9: 131670.84 | K9: 2012682.8 | L9: 📞 ติดตาม-High | M9: สูง | N9: 1 | O9: —
A10: PL612 | B10: 2026-01 | C10: สมบูรณ์อิเล็คทริค | D10: B2B อื่นๆ | E10: LKT. 2026-01 -PL612 | F10: 6 มกราคม 2026 | G10: LED Streetlight | H10: BTFL-ZC03-400W/LED FLOODLIGHT 400W/6500K | I10: 453936 | J10: 31775.52 | K10: 485711.52 | L10: 📋 ติดตาม | M10: กลาง | N10: 1 | O10: —
A11: PL614 | B11: 2026-01 | C11: โปรทูสเปรช | D11: B2B อื่นๆ | E11: LKT. 2026-01 -PL614 | F11: 7 มกราคม 2026 | G11: เสาไฟถนน | H11: Pole With Bracket 9M-T4-TR | I11: 191884 | J11: 13431.88 | K11: 205315.88 | L11: ⚪ รอผล | M11: ต่ำ | N11: 1 | O11: —
A12: PL615 | B12: 2026-01 | C12: อินโน ซิสเต็ม | D12: B2B อื่นๆ | E12: LKT. 2026-01 -PL615 | F12: 7 มกราคม 2026 | G12: Electrical Accessories | H12: ชุด Breaker 1P 10A 230V 1 SET (Plate Aluminium) | I12: 22623.3 | J12: 1583.63 | K12: 24206.93 | L12: ⚪ รอผล | M12: ต่ำ | N12: 1 | O12: —
A13: PL616 | B13: 2026-01 | C13: วิ-หลี กรุ๊ป | D13: B2B อื่นๆ | E13: LKT. 2026-01 -PL616 | F13: 7 มกราคม 2026 | G13: เสาไฟถนน | H13: Pole With Bracket 9M-T4-TR | I13: 94109.4 | J13: 6587.66 | K13: 100697.06 | L13: ⚪ รอผล | M13: ต่ำ | N13: 1 | O13: —
A14: PL617 | B14: 2026-01 | C14: PT | D14: B2B อื่นๆ | E14: LKT. 2026-01 -PL609 | F14: 6 มกราคม 2026 | G14: LED Streetlight | H14: LED Streetlight 150W 5700K 19,500lm CRI70 140D | I14: 102000 | J14: 7140 | K14: 109140 | L14: ⚪ รอผล | M14: ต่ำ | N14: 1 | O14: —
A15: PL618 | B15: 2026-01 | C15: วีระยุทธ | D15: B2B อื่นๆ | E15: LKT. 2026-01 -PL618 | F15: 7 มกราคม 2026 | G15: เสาไฟถนน | H15: Pole With Bracket 6M-T4-TR | I15: 29654.8 | J15: 2075.84 | K15: 31730.64 | L15: ⚪ รอผล | M15: ต่ำ | N15: 1 | O15: —
A16: PL619 | B16: 2026-01 | C16: ทูพีเอส | D16: B2B อื่นๆ | E16: LKT. 2026-01 -PL609 | F16: 8 มกราคม 2026 | G16: สายส่งไฟฟ้า | H16: เสาสายสงไฟฟา 115KV Single Circuit H20M | I16: 2444120 | J16: 171088.4 | K16: 2615208.4 | L16: 📞 ติดตาม-High | M16: สูง | N16: 1 | O16: —
A17: PL620 | B17: 2026-01 | C17: อินเตอร์ เอ็กซ์เพิร์ท R03 | D17: B2B อื่นๆ | E17: LKT. 2025-08 -PL337 | F17: 8 มกราคม 2026 | G17: High Mast | H17: High Mast 15 M PCD550 M32 8 Hole + วงแหวน 6 โคม REV.3 | I17: 1017041.6 | J17: 71192.91 | K17: 1088234.5 | L17: 📞 ติดตาม-High | M17: สูง | N17: 1 | O17: —
A18: PL621 | B18: 2026-01 | C18: บริษัท ทริลเลียนอินดัสตรีส์ จำกัด | D18: B2B บริษัท | E18: LKT. 2026-01 -PL609 | G18: เสาไฟถนน | H18: Post Top Pole 8M-T4-TR | I18: 115840 | J18: 8108.8 | K18: 123948.8 | L18: ⚪ รอผล | M18: ต่ำ | N18: 1 | O18: —
A19: PL622 | B19: 2026-01 | C19: อนุพงษ์ | D19: B2B อื่นๆ | E19: LKT. 2026-01 -PL622 | G19: เสาไฟถนน | H19: Pole With Bracket 9M-T4-TR | I19: 722064 | J19: 50544.48 | K19: 772608.48 | L19: 📋 ติดตาม | M19: กลาง | N19: 1 | O19: —
A20: PL623 | B20: 2026-01 | C20: ไลท์ติ้ง โซลูชั่น | D20: B2B อื่นๆ | E20: LKT. 2026-01 -PL623 | G20: เสาไฟถนน | H20: Post Top Pole 8M-T4-TR | I20: 80289.44 | J20: 5620.26 | K20: 85909.7 | L20: ⚪ รอผล | M20: ต่ำ | N20: 1 | O20: —
A21: PL624 | B21: 2026-01 | C21: เค บี เอ็ม | D21: B2B อื่นๆ | E21: LKT. 2026-01 -PL624 | G21: เสาไฟถนน | H21: ชุดวายริ่งสายไฟเขา 6 ดวงโคม | I21: 145608.4 | J21: 10192.59 | K21: 155800.99 | L21: ⚪ รอผล | M21: ต่ำ | N21: 1 | O21: อปท. Supply
A22: PL625 | B22: 2026-01 | C22: สุรัตน์ | D22: B2B อื่นๆ | E22: LKT. 2026-01 -PL625 | G22: High Mast | H22: High mast Pole 20 M วงแหวน 8 โคม เหล็ก 4.5 มม. | I22: 6904195 | J22: 483293.65 | K22: 7387488.7 | L22: 🔥 ร้อน | M22: สูงมาก | N22: 1 | O22: —
A23: PL627 | B23: 2026-01 | C23: บจก.มั่นใจ ดีเวลลอปเมนท์ | D23: B2B อื่นๆ | E23: LKT. 2026-01 -PL627 | G23: อื่นๆ | H23: อื่นๆ | I23: 16350 | J23: 1144.5 | K23: 17494.5 | L23: ⚪ รอผล | M23: ต่ำ | N23: 0 | O23: —
A24: PL628 | B24: 2026-01 | C24: ธนาภา เทคโนโลยี่ | D24: B2B อื่นๆ | E24: LKT. 2026-01 -PL628 | G24: อื่นๆ | H24: อื่นๆ | I24: 1860800 | J24: 130256 | K24: 1991056 | L24: 📞 ติดตาม-High | M24: สูง | N24: 0 | O24: —
A25: PL629 | B25: 2026-01 | C25: นราภรณ์ | D25: B2B อื่นๆ | E25: LKT. 2026-01 -PL629 | G25: เสาไฟถนน | H25: Post Top Pole 8M-T4-TR | I25: 171083.5 | J25: 11975.85 | K25: 183059.35 | L25: ⚪ รอผล | M25: ต่ำ | N25: 1 | O25: —
A26: PL630 | B26: 2026-01 | C26: ทริคอิเล็คทริค | D26: B2B อื่นๆ | E26: LKT. 2026-01 -PL630 | F26: 12 มกราคม 2025 | G26: อื่นๆ | H26: อื่นๆ | I26: 100038.4 | J26: 7002.69 | K26: 107041.09 | L26: ⚪ รอผล | M26: ต่ำ | N26: 0 | O26: —
A27: PL631 | B27: 2026-01 | C27: พี เอ็นริช | D27: B2B อื่นๆ | E27: LKT. 2026-01 -PL631 | G27: เสาไฟถนน | H27: Post Top Pole 8M-T4-TR | I27: 44688 | J27: 3128.16 | K27: 47816.16 | L27: ⚪ รอผล | M27: ต่ำ | N27: 1 | O27: —
A28: PL632 | B28: 2026-01 | C28: อินโน ซิสเต็ม | D28: B2B อื่นๆ | E28: LKT. 2026-01 -PL632 | F28: 14 มกราคม 2026 | G28: Electrical Accessories | H28: ชุดBreaker 1P, 10A, 200-240V. 1Set Plate Aluminium | I28: 16059.75 | J28: 1124.18 | K28: 17183.93 | L28: ⚪ รอผล | M28: ต่ำ | N28: 1 | O28: —
A29: PL633 | B29: 2026-01 | C29: พรบันดาลโชค | D29: B2B อื่นๆ | E29: LKT. 2026-01 -PL633 | G29: High Mast | H29: High mast Pole 20 M วงแหวน 8 โคม เหล็ก 4.5 มม. | I29: 545899.2 | J29: 38212.94 | K29: 584112.14 | L29: 📋 ติดตาม | M29: กลาง | N29: 1 | O29: —
A30: PL634 | B30: 2026-01 | C30: ไอซีซี | D30: B2B อื่นๆ | E30: LKT. 2026-01 -PL634 | G30: High Mast | H30: High mast Pole 25 M วงแหวน 8 โคม เหล็ก 6.0,4.5 มม. | I30: 432140.8 | J30: 30249.86 | K30: 462390.66 | L30: 📋 ติดตาม | M30: กลาง | N30: 1 | O30: —
A31: PL635 | B31: 2026-01 | C31: ไลท์ติ้ง โซลูชั่น | D31: B2B อื่นๆ | E31: LKT. 2026-01 -PL635 | F31: 15 มกราคม 2026 | G31: เสาไฟถนน | H31: post top 8M+Arm Bracket 2โคม | I31: 113905 | J31: 7973.35 | K31: 121878.35 | L31: ⚪ รอผล | M31: ต่ำ | N31: 1 | O31: —
A32: PL636 | B32: 2026-01 | C32: ท็อปเบสท์ แมนูแฟคเจอริ่ง | D32: B2B อื่นๆ | E32: LKT. 2026-01 -PL636 | G32: เสาไฟถนน | H32: Pole With Bracket 6M-T4-TR | I32: 444072.3 | J32: 31085.06 | K32: 475157.36 | L32: 📋 ติดตาม | M32: กลาง | N32: 1 | O32: —
A33: PL637 | B33: 2026-01 | C33: บริษัท เดอะวิน เทเลคอม จำกัด | D33: B2B บริษัท | E33: LKT. 2026-01-PL637 | F33: 15 มกราคม 2026 | G33: เสาไฟถนน | H33: เสากลมตรง 4'' H4M. HDG+ทําสีดําเงา | I33: 3044050 | J33: 213083.5 | K33: 3257133.5 | L33: 🔥 ร้อน | M33: สูงมาก | N33: 1 | O33: —
A34: PL638 | B34: 2026-01 | C34: บริษัท เอส.พี.เอส.ทราฟฟิค ไลน์ จำกัด | D34: B2B บริษัท | E34: LKT. 2026-01-PL638 | F34: 15 มกราคม 2026 | G34: อื่นๆ | H34: อื่นๆ | I34: 571830 | J34: 40028.1 | K34: 611858.1 | L34: 📋 ติดตาม | M34: กลาง | N34: 0 | O34: —
A35: PL639 | B35: 2026-01 | C35: บริษัท โกลว์ พาวเวอร์ เทคโนโลยี จำกัด-EGATJOB1 R01 | D35: B2B บริษัท | E35: LKT. 2026-01-PL638 | F35: 15 มกราคม 2026 | G35: เสาไฟถนน | H35: Pole With Bracket 5M-T4-TR | I35: 405150 | J35: 28360.5 | K35: 433510.5 | L35: 📋 ติดตาม | M35: กลาง | N35: 1 | O35: EGAT
A36: PL640 | B36: 2026-01 | C36: บริษัท โกลว์ พาวเวอร์ เทคโนโลยี จำกัด-EGATJOB2 R2 | D36: B2B บริษัท | E36: LKT. 2026-01-PL640 | F36: 18 มกราคม 2026 | G36: อื่นๆ | H36: อื่นๆ | I36: 487450 | J36: 34121.5 | K36: 521571.5 | L36: 📋 ติดตาม | M36: กลาง | N36: 0 | O36: EGAT
A37: PL641 | B37: 2026-01 | C37: บริษัท เอ็นเทค แมเนจเม้นท์ จำกัด (สำนักงานใหญ่) | D37: B2G ภาครัฐ | E37: LKT. 2026-01-PL641 | F37: 18 มกราคม 2026 | G37: อื่นๆ | H37: อื่นๆ | I37: 649600 | J37: 45472 | K37: 695072 | L37: 📋 ติดตาม | M37: กลาง | N37: 0 | O37: —
A38: PL642 | B38: 2026-01 | C38: ดาต้า เวคเตอร์ | D38: B2B อื่นๆ | E38: LKT. 2026-01 -PL642 | F38: 19 มกราคม 2025 | G38: เสาไฟถนน | H38: Post Top Pole 10M-T4-TR | I38: 14565 | J38: 1019.55 | K38: 15584.55 | L38: ⚪ รอผล | M38: ต่ำ | N38: 1 | O38: —
A39: PL643 | B39: 2026-01 | C39: กรรณเลิศ เทรดดิ้ง | D39: B2B อื่นๆ | E39: LKT. 2026-01 -PL642 | F39: 19 มกราคม 2026 | G39: High Mast | H39: Pole With Bracket 9M-T4-TR | I39: 281652 | J39: 19715.64 | K39: 301367.64 | L39: 📋 ติดตาม | M39: กลาง | N39: 1 | O39: —
A40: PL644 | B40: 2026-01 | C40: พรีไซซ | D40: B2B อื่นๆ | E40: LKT. 2026-01 -PL644 | F40: 19 มกราคม 2026 | G40: High Mast | H40: High Mast 15 M PCD550+วงแหวน 6 โคม(โดมOD890) | I40: 485874.2 | J40: 34011.19 | K40: 519885.39 | L40: 📋 ติดตาม | M40: กลาง | N40: 1 | O40: —
A41: PL645 | B41: 2026-01 | C41: ทริคอิเล็คทริค | D41: B2B อื่นๆ | E41: LKT. 2026-01 -PL645 | F41: 20 มกราคม 2025 | G41: อื่นๆ | H41: อื่นๆ | I41: 4263 | J41: 298.41 | K41: 4561.41 | L41: ⚪ รอผล | M41: ต่ำ | N41: 0 | O41: —
...

Sheet 📈 Status Dashboard
A1: LeKise | STATUS DASHBOARD | อัปเดตอัตโนมัติจาก CRM Table | กรอกสถานะตามจริงที่ Column P ใน CRM Table
A3: 💡 วิธีใช้: ไปที่ Sheet 📋 CRM Table → คอลัมน์ P "★ สถานะตามจริง" → เลือก Dropdown | Dashboard นี้จะ Update อัตโนมัติ
A5: สถานะตามจริง | B5: จำนวนใบ | C5: มูลค่ารวม (฿) | D5: % มูลค่า | E5: % ใบ | F5: เฉลี่ย/ใบ
A6: ✅ปิดได้ | B6: =COUNTIF('📋 CRM Table'!P5:P315,"✅ปิดได้") | C6: =SUMIF('📋 CRM Table'!P5:P315,"✅ปิดได้",'📋 CRM Table'!K5:K315) | D6: =IF(SUM('📋 CRM Table'!K5:K315)=0,0,C6/SUM('📋 CRM Table'!K5:K315)) | E6: =IF(COUNTA('📋 CRM Table'!P5:P315)=0,0,B6/COUNTA('📋 CRM Table'!P5:P315)) | F6: =IF(B6=0,0,C6/B6)
A7: 🔥ร้อน-ปิดเร็ว | B7: =COUNTIF('📋 CRM Table'!P5:P315,"🔥ร้อน-ปิดเร็ว") | C7: =SUMIF('📋 CRM Table'!P5:P315,"🔥ร้อน-ปิดเร็ว",'📋 CRM Table'!K5:K315) | D7: =IF(SUM('📋 CRM Table'!K5:K315)=0,0,C7/SUM('📋 CRM Table'!K5:K315)) | E7: =IF(COUNTA('📋 CRM Table'!P5:P315)=0,0,B7/COUNTA('📋 CRM Table'!P5:P315)) | F7: =IF(B7=0,0,C7/B7)
A8: 📞กำลังเจรจา | B8: =COUNTIF('📋 CRM Table'!P5:P315,"📞กำลังเจรจา") | C8: =SUMIF('📋 CRM Table'!P5:P315,"📞กำลังเจรจา",'📋 CRM Table'!K5:K315) | D8: =IF(SUM('📋 CRM Table'!K5:K315)=0,0,C8/SUM('📋 CRM Table'!K5:K315)) | E8: =IF(COUNTA('📋 CRM Table'!P5:P315)=0,0,B8/COUNTA('📋 CRM Table'!P5:P315)) | F8: =IF(B8=0,0,C8/B8)
A9: 💼ส่ง Proposal แล้ว | B9: =COUNTIF('📋 CRM Table'!P5:P315,"💼ส่ง Proposal แล้ว") | C9: =SUMIF('📋 CRM Table'!P5:P315,"💼ส่ง Proposal แล้ว",'📋 CRM Table'!K5:K315) | D9: =IF(SUM('📋 CRM Table'!K5:K315)=0,0,C9/SUM('📋 CRM Table'!K5:K315)) | E9: =IF(COUNTA('📋 CRM Table'!P5:P315)=0,0,B9/COUNTA('📋 CRM Table'!P5:P315)) | F9: =IF(B9=0,0,C9/B9)
A10: ⏳รอลูกค้าตอบ | B10: =COUNTIF('📋 CRM Table'!P5:P315,"⏳รอลูกค้าตอบ") | C10: =SUMIF('📋 CRM Table'!P5:P315,"⏳รอลูกค้าตอบ",'📋 CRM Table'!K5:K315) | D10: =IF(SUM('📋 CRM Table'!K5:K315)=0,0,C10/SUM('📋 CRM Table'!K5:K315)) | E10: =IF(COUNTA('📋 CRM Table'!P5:P315)=0,0,B10/COUNTA('📋 CRM Table'!P5:P315)) | F10: =IF(B10=0,0,C10/B10)
A11: ❌พัก/ไม่ซื้อ | B11: =COUNTIF('📋 CRM Table'!P5:P315,"❌พัก/ไม่ซื้อ") | C11: =SUMIF('📋 CRM Table'!P5:P315,"❌พัก/ไม่ซื้อ",'📋 CRM Table'!K5:K315) | D11: =IF(SUM('📋 CRM Table'!K5:K315)=0,0,C11/SUM('📋 CRM Table'!K5:K315)) | E11: =IF(COUNTA('📋 CRM Table'!P5:P315)=0,0,B11/COUNTA('📋 CRM Table'!P5:P315)) | F11: =IF(B11=0,0,C11/B11)
A12: 🔄Revise ราคา | B12: =COUNTIF('📋 CRM Table'!P5:P315,"🔄Revise ราคา") | C12: =SUMIF('📋 CRM Table'!P5:P315,"🔄Revise ราคา",'📋 CRM Table'!K5:K315) | D12: =IF(SUM('📋 CRM Table'!K5:K315)=0,0,C12/SUM('📋 CRM Table'!K5:K315)) | E12: =IF(COUNTA('📋 CRM Table'!P5:P315)=0,0,B12/COUNTA('📋 CRM Table'!P5:P315)) | F12: =IF(B12=0,0,C12/B12)
A13: ⚪ยังไม่ติดต่อ | B13: =COUNTIF('📋 CRM Table'!P5:P315,"⚪ยังไม่ติดต่อ") | C13: =SUMIF('📋 CRM Table'!P5:P315,"⚪ยังไม่ติดต่อ",'📋 CRM Table'!K5:K315) | D13: =IF(SUM('📋 CRM Table'!K5:K315)=0,0,C13/SUM('📋 CRM Table'!K5:K315)) | E13: =IF(COUNTA('📋 CRM Table'!P5:P315)=0,0,B13/COUNTA('📋 CRM Table'!P5:P315)) | F13: =IF(B13=0,0,C13/B13)
A14: รวมทั้งหมด (ที่กรอกสถานะ) | B14: =COUNTA('📋 CRM Table'!P5:P315) | C14: =SUM('📋 CRM Table'!K5:K315)
A16: 📊 สถานะ Auto (จาก Pipeline Value) — ข้อมูลอ้างอิงจาก CRM Table คอลัมน์ L
A17: 🔥 ร้อน | B17: ≥ 3,000,000 ฿ | C17: =COUNTIF('📋 CRM Table'!L5:L315,"*🔥*") | D17: =SUMIF('📋 CRM Table'!L5:L315,"*🔥*",'📋 CRM Table'!K5:K315)
A18: 📞 ติดตาม-High | B18: 1,000,000 – 2,999,999 ฿ | C18: =COUNTIF('📋 CRM Table'!L5:L315,"*📞*") | D18: =SUMIF('📋 CRM Table'!L5:L315,"*📞*",'📋 CRM Table'!K5:K315)
A19: 📋 ติดตาม | B19: 300,000 – 999,999 ฿ | C19: =COUNTIF('📋 CRM Table'!L5:L315,"*📋*") | D19: =SUMIF('📋 CRM Table'!L5:L315,"*📋*",'📋 CRM Table'!K5:K315)
A20: ⚪ รอผล | B20: < 300,000 ฿ | C20: =COUNTIF('📋 CRM Table'!L5:L315,"*⚪*") | D20: =SUMIF('📋 CRM Table'!L5:L315,"*⚪*",'📋 CRM Table'!K5:K315)

Sheet 👥 Customer CRM
A1: LeKise | Customer CRM 2026 | 273 ลูกค้า | 16 มิ.ย. 2569
A3: # | B3: ชื่อลูกค้า | C3: ประเภท | D3: Deal | E3: มูลค่า (฿) | F3: % | G3: กลุ่มสินค้า | H3: เดือน | I3: PL | J3: ระดับ CRM | K3: กลุ่มงาน | L3: Action
A4: 1 | B4: กรรณเลิศ เทรดดิ้ง | C4: B2B อื่นๆ | D4: 3 | E4: 9826598.3 | F4: 5.3% | G4: High Mast/เสาไฟถนน | H4: 2026-01, 2026-02 | I4: PL682 | J4: A - VIP | K4: — | L4: 📞 ติดตามด่วน
A5: 2 | B5: ภิรมย์ กรุ๊ป | C5: B2B อื่นๆ | D5: 1 | E5: 9536178.1 | F5: 5.2% | G5: High Mast | H5: 2026-06 | I5: PL915 | J5: A - VIP | K5: — | L5: 📞 ติดตามด่วน
A6: 3 | B6: สุรัตน์ | C6: B2B อื่นๆ | D6: 1 | E6: 7387488.7 | F6: 4.0% | G6: High Mast | H6: 2026-01 | I6: PL625 | J6: A - VIP | K6: — | L6: 📞 ติดตามด่วน
A7: 4 | B7: ห้างหุ้นส่วนจำกัด สมบูรณ์อิเล็กทริค หนองบัวลำภู | C7: B2B หจก. | D7: 1 | E7: 6855170.1 | F7: 3.7% | G7: Guard Rail / การ์ดเรล | H7: 2026-05 | I7: PL874 | J7: A - VIP | K7: — | L7: 📞 ติดตามด่วน
A8: 5 | B8: ต้นตะวัน | C8: B2B อื่นๆ | D8: 1 | E8: 5807540 | F8: 3.2% | G8: เสาไฟถนน | H8: 2026-06 | I8: PL932 | J8: A - VIP | K8: — | L8: 📞 ติดตามด่วน
A9: 6 | B9: วันชัยการไฟฟ้า HM20_8 | C9: B2B อื่นๆ | D9: 1 | E9: 4709493.3 | F9: 2.6% | G9: High Mast | H9: 2026-05 | I9: PL861 | J9: A - VIP | K9: — | L9: 📞 ติดตามด่วน
A10: 7 | B10: วันชัยการไฟฟ้า | C10: B2B อื่นๆ | D10: 1 | E10: 4425301.7 | F10: 2.4% | G10: High Mast | H10: 2026-01 | I10: PL658 | J10: A - VIP | K10: — | L10: 📞 ติดตามด่วน
A11: 8 | B11: เบตเตอร์ เวิร์ลด | C11: B2B อื่นๆ | D11: 1 | E11: 3838838.6 | F11: 2.1% | G11: Guard Rail / การ์ดเรล | H11: 2026-05 | I11: PL850 | J11: A - VIP | K11: — | L11: 📞 ติดตามด่วน
A12: 9 | B12: เทศบาลนครเชียงใหม่ | C12: B2G อปท. | D12: 1 | E12: 3805428.2 | F12: 2.1% | G12: เสาไฟถนน | H12: 2026-04 | I12: PL828 | J12: A - VIP | K12: — | L12: 📞 ติดตามด่วน
A13: 10 | B13: วันชัยการไฟฟ้า 2019 | C13: B2B อื่นๆ | D13: 1 | E13: 3578683 | F13: 1.9% | G13: High Mast | H13: 2026-06 | I13: PL919 | J13: A - VIP | K13: — | L13: 📞 ติดตามด่วน
A14: 11 | B14: บริษัท เดอะวิน เทเลคอม จำกัด | C14: B2B บริษัท | D14: 1 | E14: 3257133.5 | F14: 1.8% | G14: เสาไฟถนน | H14: 2026-01 | I14: PL637 | J14: A - VIP | K14: — | L14: 📞 ติดตามด่วน
A15: 12 | B15: เค บี เอ็ม _25ม. 15 | C15: B2B อื่นๆ | D15: 1 | E15: 2747332 | F15: 1.5% | G15: High Mast | H15: 2026-05 | I15: PL908 | J15: B - สำคัญ | K15: อปท. Supply | L15: 📋 นัดหมาย
... A24: 21 | B24: บ.ยูเนียน ทราฟฟิค | C24: B2B อื่นๆ | D24: 1 | E24: 2104569.6 | F24: 1.1% | G24: Guard Rail / การ์ดเรล | H24: 2026-04 | I24: PL837 | J24: B - สำคัญ | K24: — | L24: 📋 นัดหมาย
A25: 22 | C25: B2B อื่นๆ | D25: 3 | E25: 2035615.7 | F25: 1.1% | G25: LED Streetlight/เสาไฟถนน | H25: 2026-04, 2026-05 | I25: PL869 | J25: B - สำคัญ | K25: — | L25: 📋 นัดหมาย
A26: 23 | B26: เอสไลน์พาวเวอร์ [Dealer ใต้] | C26: B2B อื่นๆ | D26: 1 | E26: 2029250.7 | F26: 1.1% | G26: เสาไฟถนน | H26: 2026-05 | I26: PL853 | J26: B - สำคัญ | K26: — | L26: 📋 นัดหมาย
A27: 24 | B27: สมบูรณ์อิเล็คทริค | C27: B2B อื่นๆ | D27: 3 | E27: 2013359.1 | F27: 1.1% | G27: High Mast/LED Streetlight | H27: 2026-01, 2026-03 | I27: PL765 | J27: B - สำคัญ | K27: — | L27: 📋 นัดหมาย
A28: 25 | B28: ที เค | C28: B2B อื่นๆ | D28: 1 | E28: 2012682.8 | F28: 1.1% | G28: เสาไฟถนน | H28: 2026-01 | I28: PL610 | J28: B - สำคัญ | K28: — | L28: 📋 นัดหมาย
A29: 26 | B29: ธนาภา เทคโนโลยี่ | C29: B2B อื่นๆ | D29: 1 | E29: 1991056 | F29: 1.1% | G29: อื่นๆ | H29: 2026-01 | I29: PL628 | J29: B - สำคัญ | K29: — | L29: 📋 นัดหมาย
A30: 27 | B30: ไลท์อัพ | C30: B2B อื่นๆ | D30: 2 | E30: 1760687.1 | F30: 1.0% | G30: High Mast/เสาไฟถนน | H30: 2026-02 | I30: PL735 | J30: B - สำคัญ | K30: — | L30: 📋 นัดหมาย
A31: 28 | B31: บิว | C31: B2B อื่นๆ | D31: 1 | E31: 1706890.1 | F31: 0.9% | G31: เสาไฟถนน | H31: 2026-05 | I31: PL887 | J31: B - สำคัญ | K31: — | L31: 📋 นัดหมาย
A32: 29 | B32: บริษัท บริลลิแอนซ์ จำกัด | C32: B2B บริษัท | D32: 1 | E32: 1641059 | F32: 0.9% | G32: เสาไฟถนน | H32: 2026-06 | I32: PL924 | J32: B - สำคัญ | K32: — | L32: 📋 นัดหมาย
A33: 30 | B33: ไอซีซี | C33: B2B อื่นๆ | D33: 5 | E33: 1586700 | F33: 0.9% | G33: High Mast/อื่นๆ | H33: 2026-03, 2026-04 | I33: PL841 | J33: B - สำคัญ | K33: — | L33: 📋 นัดหมาย
A34: 31 | B34: บ.เอส.บี.อินดัสทรี ซัพพลาย R01 | C34: B2B อื่นๆ | D34: 1 | E34: 1560966.9 | F34: 0.8% | G34: High Mast | H34: 2026-02 | I34: PL708 | J34: B - สำคัญ | K34: — | L34: 📋 นัดหมาย
A35: 32 | B35: เอเชี่ยน | C35: B2B อื่นๆ | D35: 2 | E35: 1556804 | F35: 0.8% | G35: High Mast/เสาไฟถนน | H35: 2026-03 | I35: PL785 | J35: B - สำคัญ | K35: — | L35: 📋 นัดหมาย
A36: 33 | B36: กรมท่าอากาศ | C36: B2G ภาครัฐ | D36: 1 | E36: 1503082.5 | F36: 0.8% | G36: High Mast | H36: 2026-02 | I36: PL701 | J36: B - สำคัญ | K36: — | L36: 📋 นัดหมาย
A37: 34 | B37: บ.ควินตัส แอดวานซ์ | C37: B2B อื่นๆ | D37: 2 | E37: 1461384.6 | F37: 0.8% | G37: High Mast | H37: 2026-03, 2026-04 | I37: PL822 | J37: B - สำคัญ | K37: DOA | L37: 📋 นัดหมาย
... A276: 273 | B276: บ.คินเดน | C276: B2B อื่นๆ | D276: 1 | E276: 0 | F276: 0.0% | G276: อื่นๆ | H276: 2026-06 | I276: PL931 | J276: D - รอผล | K276: — | L276: ⚪ รอสอบถาม

Sheet 🏢 Business Groups
A1: LeKise | กลุ่มงาน EGAT / DOA / ZETA-iOT / อปท. Supply | 16 มิ.ย. 2569
A3: 🏭 กลุ่มงาน EGAT (การไฟฟ้าฝ่ายผลิต) — รวม บ.โกลว์ พาวเวอร์ เทคโนโลยี จำกัด | 3 รายการ | 2.26M ฿
A4: # | B4: ชื่อลูกค้า | C4: เดือน | D4: สินค้าหลัก | E4: PL No. | F4: ก่อน VAT | G4: รวม incl VAT
A5: 1 | B5: บริษัท โกลว์ พาวเวอร์ เทคโนโลยี จำกัด-EGATJOB1 R01 | C5: 2026-01 | D5: Pole With Bracket 5M-T4-TR | E5: PL639 | F5: 405150 | G5: 433510.5
A6: 2 | B6: บริษัท โกลว์ พาวเวอร์ เทคโนโลยี จำกัด-EGATJOB2 R2 | C6: 2026-01 | D6: อื่นๆ | E6: PL640 | F6: 487450 | G6: 521571.5
A7: 3 | B7: บริษัท โกลว์ พาวเวอร์ เทคโนโลยี จำกัด | C7: 2026-05 | D7: อื่นๆ | E7: PL875 | F7: 1218700 | G7: 1304009
A8: รวม EGAT | F8: 2111300 | G8: 2259091
A10: 🌾 กลุ่มงาน DOA (กรมวิชาการเกษตร) — ควินตัส / เดลต้า พลัส / เจมินี เทค | 6 รายการ | 3.07M ฿
A11: # | B11: ชื่อลูกค้า | C11: เดือน | D11: สินค้าหลัก | E11: PL No. | F11: ก่อน VAT | G11: รวม incl VAT
A12: 1 | B12: บ.ควินตัส แอดวานซ์ | C12: 2026-03 | D12: High Mast 25M+Support 3ชั้น H1400 L | E12: PL772 | F12: 1299540 | G12: 1390507.8
A13: 2 | B13: บ.ควินตัส แอดวานซ์ | C13: 2026-04 | D13: ชุดMotorขับวงแหวนขึ้นลง 3 เฟส | E13: PL822 | F13: 66240 | G13: 70876.8
A14: 3 | B14: บ.เจมินี เทค กรมท่ากระบี่ | C14: 2026-04 | D14: Pole With Bracket 9M-T4-TR | E14: PL824 | F14: 589950 | G14: 631246.5
A15: 4 | B15: เดลต้า พลัส ชุดเกียร์วินซ์คู่ | C15: 2026-05 | D15: ชุดเกียรวินซคู+ซัพพอรตเกียร+ชุ | E15: PL851 | F15: 118750 | G15: 127062.5
A16: 5 | B16: บ.เจมินี เทค กรมท่ากระบี่ | C16: 2026-05 | D16: อื่นๆ | E16: PL909 | F16: 350550 | G16: 375088.5
A17: 6 | B17: เดลต้า พลัส เอ็นจิเนียริ่ง | C17: 2026-06 | D17: High Mast 10M 6t+Support 2ชั้น H700 | E17: PL923 | F17: 440200 | G17: 471014
A18: รวม DOA | F18: 2865230 | G18: 3065796.1
A20: 📡 กลุ่มงาน ZETA-iOT — ซีซีทีวี / ZETA-9 Cloud / คาแนล วัน | 6 รายการ | 2.17M ฿
A21: # | B21: ชื่อลูกค้า | C21: เดือน | D21: สินค้าหลัก | E21: PL No. | F21: ก่อน VAT | G21: รวม incl VAT
A22: 1 | B22: ZETA-SI / บริษัท ซีซีทีวี (ประเทศไทย) จำกัด | C22: 2026-04 | D22: อื่นๆ | E22: PL811 | F22: 838750 | G22: 897462.5
A23: 2 | B23: ZETA-9 Cloud (Controller) | C23: 2026-04 | D23: อื่นๆ | E23: PL816 | F23: 3750 | G23: 4012.5
A24: 3 | B24: SI / บริษัท ซีซีทีวี (ประเทศไทย) จำกัด | C24: 2026-04 | D24: อื่นๆ | E24: PL817 | F24: 838750 | G24: 897462.5
A25: 4 | B25: บริษัท ซีซีทีวี (ประเทศไทย) จำกัด | C25: 2026-04 | D25: Adaptor L200 OD60.5x4t Rev.01 | E25: PL827 | F25: 128250 | G25: 137227.5
A26: 5 | B26: SI / บริษัท ซีซีทีวี (ประเทศไทย) จำกัด | C26: 2026-04 | D26: Street Light Cover E27 | E26: PL847 | F26: 21350 | G26: 22844.5
A27: 6 | B27: ZETA-9 Cloud / บริษัท คาแนล วัน จำกัด | C27: 2026-05 | D27: อื่นๆ | E27: PL911 | F27: 193050 | G27: 206563.5
A28: รวม ZETA-iOT | F28: 2023900 | G28: 2165573
A30: 🏛️ กลุ่มงาน อปท. Supply — เค บี เอ็ม เทคโนโลยี จำกัด | 10 รายการ | 5.82M ฿
A31: # | B31: ชื่อลูกค้า | C31: เดือน | D31: สินค้าหลัก | E31: PL No. | F31: ก่อน VAT | G31: รวม incl VAT
A32: 1 | B32: เค บี เอ็ม | C32: 2026-01 | D32: ชุดวายริ่งสายไฟเขา 6 ดวงโคม | E32: PL624 | F32: 145608.4 | G32: 155800.99
A33: 2 | B33: เค บี เอ็ม | C33: 2026-01 | D33: High mast Pole 20 M วงแหวน 8 โคม เห | E33: PL649 | F33: 162660.4 | G33: 174046.63
A34: 3 | B34: เค บี เอ็ม | C34: 2026-04 | D34: Ground Rod for hightmass pole | E34: PL831 | F34: 133344 | G34: 142678.08
A35: 4 | B35: เค บี เอ็ม เสา HM 30ม. | C35: 2026-05 | D35: High mast Pole 30 M วงแหวน 8 โคม เห | E35: PL856 | F35: 342216 | G35: 366171.12
A36: 5 | B36: เค บี เอ็ม 15 ม. | C36: 2026-05 | D36: High mast Pole 15 M วงแหวน 6โคม | E36: PL864 | F36: 330064 | G36: 353168.48
A37: 6 | B37: เค บี เอ็ม | C37: 2026-05 | D37: อื่นๆ | E37: PL886 | F37: 70716.8 | G37: 75666.98
A38: 7 | B38: เค บี เอ็ม | C38: 2026-05 | D38: โคมกันนํ้ากันฝุน FT-TUBEPROTECT/VE | E38: PL891 | F38: 7497 | G38: 8021.79
A39: 8 | B39: เค บี เอ็ม 15ม. | C39: 2026-05 | D39: High Mast 15M วงแหวน 8 โคม 11 ลอน | E39: PL905 | F39: 711872 | G39: 761703.04
A40: 9 | B40: เค บี เอ็ม _25ม. 15 | C40: 2026-05 | D40: High Mast 25 M + Stadium 3 ชั้น 15 | E40: PL908 | F40: 2567600 | G40: 2747332
A41: 10 | B41: เค บี เอ็ม 18ม. | C41: 2026-06 | D41: Set L-Bolt M32 L800 PCD619 | E41: PL933 | F41: 967260 | G41: 1034968.2
A42: รวม อปท. Supply | F42: 5438838.6 | G42: 5819557.3

Sheet 🛡️ Guard Rail
A1: LeKise | Guard Rail / การ์ดเรล | 21 รายการ | 17.26M ฿ | 16 มิ.ย. 2569
A3: Pipeline Guard Rail รวม: 17.26M ฿ | 21 รายการ
A4: # | B4: ชื่อลูกค้า | C4: เดือน | D4: PL No. | E4: สินค้า | F4: ก่อน VAT (฿) | G4: VAT 7% | H4: รวม incl VAT | I4: สถานะ (Auto) | J4: กลุ่มงาน
A5: 1 | B5: ห้างหุ้นส่วนจำกัด สมบูรณ์อิเล็กทริค หนองบัวลำภู | C5: 2026-05 | D5: PL874 | E5: เสาการดเรล OD100 H2.0M | F5: 6406701 | G5: 448469.07 | H5: 6855170.1 | I5: 🔥 ร้อน | J5: —
A6: 2 | B6: เบตเตอร์ เวิร์ลด | C6: 2026-05 | D6: PL850 | E6: เสาการดเรล OD100 H2.0M (เชื่อมเพลท) | F6: 3587699.6 | G6: 251138.97 | H6: 3838838.6 | I6: 🔥 ร้อน | J6: —
A7: 3 | B7: บ.ยูเนียน ทราฟฟิค | C7: 2026-04 | D7: PL837 | E7: เสาการดเรล OD100 H2.0M | F7: 1966887.4 | G7: 137682.12 | H7: 2104569.6 | I7: 📞 ติดตาม-High | J7: —
A8: 4 | B8: อี อี เอส ที เรซซิ่ง 2.5 | C8: 2026-05 | D8: PL901 | E8: เสาการดเรล OD100 H2.0M | F8: 867167.7 | G8: 60701.74 | H8: 927869.44 | I8: 📋 ติดตาม | J8: —
A9: 5 | B9: องค์การบริหารส่วนตำบลตาขัน | C9: 2026-06 | D9: PL939 | E9: การ์ดเรล Ø60.3×3.2t สีเทา | F9: 845503.41 | G9: 59185.24 | H9: 904688.65 | I9: 📋 ติดตาม | J9: —
A10: 6 | B10: ส่องกิจก่อสร้าง 3.2 | C10: 2026-05 | D10: PL881 | E10: เสาการดเรล OD100 H2.0M | F10: 522547.76 | G10: 36578.34 | H10: 559126.1 | I10: 📋 ติดตาม | J10: —
A11: 7 | B11: สมบูรณ์อิเลคทริค หนองบัวลำภู | C11: 2026-05 | D11: PL871 | E11: ชุดวายริ่งสายไฟเขา 6 ดวงโคม | F11: 299684 | G11: 20977.88 | H11: 320661.88 | I11: 📋 ติดตาม | J11: —
A12: 8 | B12: คุณนพกร | C12: 2026-06 | D12: PL936 | E12: การ์ดเรล Ø48.3×2.5t สีขาว-แดง | F12: 299651.52 | G12: 20975.61 | H12: 320627.13 | I12: 📋 ติดตาม | J12: —
A13: 9 | B13: กัณฑพงษ์ | C13: 2026-02 | D13: PL720 | E13: Pole With Bracket 9M-T4-TR | F13: 232848 | G13: 16299.36 | H13: 249147.36 | I13: ⚪ รอผล | J13: —
A14: 10 | B14: นพพร สุมงคล 2.5 | C14: 2026-05 | D14: PL865 | E14: เสาการดเรล OD100 H2.0M | F14: 190686.44 | G14: 13348.05 | H14: 204034.49 | I14: ⚪ รอผล | J14: —
A15: 11 | B15: พรุดินนา ดีไซน์ | C15: 2026-06 | D15: PL922 | E15: เสาการดเรล OD100 H2.0M | F15: 182056.39 | G15: 12743.95 | H15: 194800.34 | I15: ⚪ รอผล | J15: —
A16: 12 | B16: วิภาสกฤต บำรุงพืช | C16: 2026-05 | D16: PL879 | E16: เสาการดเรล OD100 H2.0M | F16: 178626.56 | G16: 12503.86 | H16: 191130.42 | I16: ⚪ รอผล | J16: —
... A25: 21 | B25: คุณจัสมิน | C25: 2026-04 | D25: PL810 | E25: เสาการดเรล OD100 H2.0M (เชื่อมเพลท) | F25: 4688.32 | G25: 328.18 | H25: 5016.5 | I25: ⚪ รอผล | J25: —
A26: รวม Guard Rail / การ์ดเรล — 21 รายการ | F26: 16131732 | G26: 1129221.2 | H26: 17260953

Sheet 📦 Product Matrix
A1: LeKise | Product × Month Matrix 2026 | 16 มิ.ย. 2569
A3: กลุ่มสินค้า / เดือน | B3: 2026-01 | C3: 2026-02 | D3: 2026-03 | E3: 2026-04 | F3: 2026-05 | G3: 2026-06 | H3: รวม | I3: % | J3: ใบ
A4: High Mast | B4: 27712859 | C4: 9053089 | D4: 6229862.3 | E4: 2050676.4 | F4: 12674263 | G4: 19419528 | H4: 77140277 | I4: 42.0% | J4: 74
A5: Guard Rail / การ์ดเรล | C5: 249147.36 | D5: 169613.14 | E5: 2235328.9 | F5: 13169879 | G5: 1436985 | H5: 17260953 | I5: 9.4% | J5: 21
A6: เสาไฟถนน | B6: 15528660 | C6: 6731310.1 | D6: 9305980.1 | E6: 10095110 | F6: 11133661 | G6: 8953140.8 | H6: 61747862 | I6: 33.6% | J6: 133
A7: LED Streetlight | B7: 1142580.2 | C7: 264238.64 | D7: 656500.11 | E7: 1645272.2 | G7: 863312.38 | H7: 4571903.6 | I7: 2.5% | J7: 15
A8: LED Floodlight | C8: 2110831.8 | E8: 952390.95 | F8: 88292.12 | H8: 3151514.9 | I8: 1.7% | J8: 4
A9: LED Highbay | B9: 204057.56 | D9: 62412.67 | H9: 266470.23 | I9: 0.1% | J9: 2
A10: Solar | B10: 55481.59 | D10: 619874.33 | H10: 675355.92 | I10: 0.4% | J10: 3
A11: สายส่งไฟฟ้า | B11: 2615208.4 | H11: 2615208.4 | I11: 1.4% | J11: 1
A12: Hardware / Accessories | C12: 111176.85 | D12: 9395.46 | H12: 120572.31 | I12: 0.1% | J12: 3
A13: Electrical Accessories | B13: 41390.86 | C13: 54708.03 | H13: 96098.89 | I13: 0.1% | J13: 3
A14: อื่นๆ | B14: 5161933.3 | C14: 2802356.1 | D14: 2697503.9 | E14: 2232769 | F14: 2951741 | G14: 349941.94 | H14: 16196245 | I14: 8.8% | J14: 52
A15: รวมทุกกลุ่ม | B15: 52462171 | C15: 21376858 | D15: 19751142 | E15: 19211547 | F15: 40017836 | G15: 31022908 | H15: 1.8384246e+08 | I15: 100% | J15: 311

Sheet ✅ Follow-Up Tracker
A1: LeKise | Follow-Up Tracker | Priority Order | 16 มิ.ย. 2569
A3: ใบเสนอ ≥ 100,000 บาท | 216 รายการ | รวม 180.3M ฿ | 16 มิ.ย. 2569
A4: # | B4: PL No. | C4: ชื่อลูกค้า | D4: เดือน | E4: สินค้าหลัก | F4: เลขที่ใบเสนอ | G4: ก่อน VAT | H4: VAT 7% | I4: รวม incl VAT | J4: สถานะ (Auto) | K4: สถานะตามจริง | L4: ความสำคัญ | M4: กลุ่มงาน | N4: Action
A5: 1 | B5: PL915 | C5: ภิรมย์ กรุ๊ป | D5: 2026-06 | E5: High mast Pole 25 M วงแหวน 10 | F5: LKT. 2026-06 -PL915 | G5: 8912316 | H5: 623862.12 | I5: 9536178.1 | J5: 🔥 ร้อน | K5: — | L5: สูงมาก | M5: — | N5: 📞 ติดตามด่วน!
A6: 2 | B6: PL654 | C6: กรรณเลิศ เทรดดิ้ง | D6: 2026-01 | E6: High mast Pole 20 M วงแหวน 8 โ | F6: LKT. 2026-01 -PL642 | G6: 8216697.2 | H6: 575168.81 | I6: 8791866.1 | J6: 🔥 ร้อน | K6: — | L6: สูงมาก | M6: — | N6: 📞 ติดตามด่วน!
A7: 3 | B7: PL625 | C7: สุรัตน์ | D7: 2026-01 | E7: High mast Pole 20 M วงแหวน 8 โ | F7: LKT. 2026-01 -PL625 | G7: 6904195 | H7: 483293.65 | I7: 7387488.7 | J7: 🔥 ร้อน | K7: — | L7: สูงมาก | M7: — | N7: 📞 ติดตามด่วน!
A8: 4 | B8: PL874 | C8: ห้างหุ้นส่วนจำกัด สมบูรณ์อิเล็กทริค หนองบัวลำภู | D8: 2026-05 | E8: เสาการดเรล OD100 H2.0M | F8: LKT. 2026-05-869 | G8: 6406701 | H8: 448469.07 | I8: 6855170.1 | J8: 🔥 ร้อน | K8: — | L8: สูงมาก | M8: — | N8: 📞 ติดตามด่วน!
A9: 5 | B9: PL932 | C9: ต้นตะวัน | D9: 2026-06 | E9: Pole With Bracket 12M-T4-TR (ช | F9: LKT. 2026-06 -PL932 | G9: 5427607.5 | H9: 379932.53 | I9: 5807540 | J9: 🔥 ร้อน | K9: — | L9: สูงมาก | M9: — | N9: 📞 ติดตามด่วน!
A10: 6 | B10: PL861 | C10: วันชัยการไฟฟ้า HM20_8 | D10: 2026-05 | E10: HIGH MAST POLE 20M วงแหวน 8โคม | F10: LKT. 2026-05 -PL861 | G10: 4401395.6 | H10: 308097.69 | I10: 4709493.3 | J10: 🔥 ร้อน | K10: — | L10: สูงมาก | M10: — | N10: 📞 ติดตามด่วน!
A11: 7 | B11: PL658 | C11: วันชัยการไฟฟ้า | D11: 2026-01 | E11: HIGH MAST POLE 20M วงแหวน 8โคม | F11: LKT. 2026-01 -PL658 | G11: 4135796 | H11: 289505.72 | I11: 4425301.7 | J11: 🔥 ร้อน | K11: — | L11: สูงมาก | M11: — | N11: 📞 ติดตามด่วน!
A12: 8 | B12: PL850 | C12: เบตเตอร์ เวิร์ลด | D12: 2026-05 | E12: เสาการดเรล OD100 H2.0M (เชื่อ | F12: LKT. 2026-05 -PL851 | G12: 3587699.6 | H12: 251138.97 | I12: 3838838.6 | J12: 🔥 ร้อน | K12: — | L12: สูงมาก | M12: — | N12: 📞 ติดตามด่วน!
A13: 9 | B13: PL828 | C13: เทศบาลนครเชียงใหม่ | D13: 2026-04 | E13: Pole With Bracket 9M-T4-TR | F13: LKT. 2026-01 -PL613 | G13: 3556475 | H13: 248953.25 | I13: 3805428.2 | J13: 🔥 ร้อน | K13: — | L13: สูงมาก | M13: — | N13: 📞 ติดตามด่วน!
A14: 10 | B14: PL919 | C14: วันชัยการไฟฟ้า 2019 | D14: 2026-06 | E14: HIGH MAST POLE 20M วงแหวน 8โคม | F14: LKT. 2026-06 -PL919 | G14: 3344563.6 | H14: 234119.45 | I14: 3578683 | J14: 🔥 ร้อน | K14: — | L14: สูงมาก | M14: — | N14: 📞 ติดตามด่วน!
A15: 11 | B15: PL637 | C15: บริษัท เดอะวิน เทเลคอม จำกัด | D15: 2026-01 | E15: เสากลมตรง 4'' H4M. HDG+ทําสีดํ | F15: LKT. 2026-01-PL637 | G15: 3044050 | H15: 213083.5 | I15: 3257133.5 | J15: 🔥 ร้อน | K15: — | L15: สูงมาก | M15: — | N15: 📞 ติดตามด่วน!
A16: 12 | B16: PL908 | C16: เค บี เอ็ม _25ม. 15 | D16: 2026-05 | E16: High Mast 25 M + Stadium 3 ชั้ | F16: LKT. 2026-05 -PL908 | G16: 2567600 | H16: 179732 | I16: 2747332 | J16: 📞 ติดตาม-High | K16: — | L16: สูง | M16: อปท. Supply | N16: 📋 นัดประชุม
... A56: 52 | B56: PL862 | C56: เอ็ม เอ็น | D56: 2026-05 | E56: Pole With Bracket 9M-T4-TR | F56: LKT. 2026-05 -PL862 | G56: 805011.2 | H56: 56350.78 | I56: 861361.98 | J56: 📋 ติดตาม | K56: — | L56: กลาง | M56: — | N56: 📧 ส่ง Email
A57: 53 | B57: PL869 | D57: 2026-05 | E57: Pole With Bracket 9M-T4-TR | F57: LKT. 2026-05 -PL862 | G57: 805011.2 | H57: 56350.78 | I57: 861361.98 | J57: 📋 ติดตาม | K57: — | L57: กลาง | M57: — | N57: 📧 ส่ง Email
A58: 54 | B58: PL898 | C58: ฐิดาภา ขันทอง | D58: 2026-05 | E58: HIGH MAST POLE 18M วงแหวน 10โค | F58: LKT. 2026-05-PL898 | G58: 793447.2 | H58: 55541.3 | I58: 848988.5 | J58: 📋 ติดตาม | K58: — | L58: กลาง | M58: — | N58: 📧 ส่ง Email
A59: 55 | B59: PL622 | C59: อนุพงษ์ | D59: 2026-01 | E59: Pole With Bracket 9M-T4-TR | F59: LKT. 2026-01 -PL622 | G59: 722064 | H59: 50544.48 | I59: 772608.48 | J59: 📋 ติดตาม | K59: — | L59: กลาง | M59: — | N59: 📧 ส่ง Email
A60: 56 | B60: PL905 | C60: เค บี เอ็ม 15ม. | D60: 2026-05 | E60: High Mast 15M วงแหวน 8 โคม 11 | F60: LKT. 2026-05 -PL905 | G60: 711872 | H60: 49831.04 | I60: 761703.04 | J60: 📋 ติดตาม | K60: — | L60: กลาง | M60: อปท. Supply | N60: 📧 ส่ง Email
A61: 57 | B61: PL34 | D61: 2026-04 | E61: กิ่ง (ทอกลมหนา 2.3mm.) ขนาด 2 | F61: LKT. 2026-04 -PL819 | G61: 711088 | H61: 49776.16 | I61: 760864.16 | J61: 📋 ติดตาม | K61: — | L61: กลาง | M61: — | N61: 📧 ส่ง Email
A62: 58 | B62: PL819 | C62: อริ | D62: 2026-04 | E62: กิ่ง (ทอกลมหนา 2.3mm.) ขนาด 2 | F62: LKT. 2026-04 -PL819 | G62: 711088 | H62: 49776.16 | I62: 760864.16 | J62: 📋 ติดตาม | K62: — | L62: กลาง | M62: — | N62: 📧 ส่ง Email
A63: 59 | B63: PL930 | C63: เอชาย เทคโนโลยี | D63: 2026-06 | E63: RT-7A81-15057 โคมไฟถนน Street | F63: LKT. 2026-06 -PL930 | G63: 710010 | H63: 49700.7 | I63: 759710.7 | J63: 📋 ติดตาม | K63: — | L63: กลาง | M63: — | N63: 📧 ส่ง Email
A64: 60 | B64: PL777 | C64: วิ-หลี | D64: 2026-03 | E64: Pole With Bracket 9M-T4-TR | F64: LKT. 2026-03 -PL777 | G64: 699426 | H64: 48959.82 | I64: 748385.82 | J64: 📋 ติดตาม | K64: — | L64: กลาง | M64: — | N64: 📧 ส่ง Email
A65: 61 | B65: PL682 | C65: กรรณเลิศ เทรดดิ้ง | D65: 2026-02 | E65: ฿55.00 | F65: LKT. 2026-02 -PL682 | G65: 685387.5 | H65: 47977.13 | I65: 733364.63 | J65: 📋 ติดตาม | K65: — | L65: กลาง | M65: — | N65: 📧 ส่ง Email
A66: 62 | B66: PL880 | C66: ณัชนันท์ พีเอ | D66: 2026-05 | E66: ชุดวายริ่งสายไฟ 6 ดวงโคม (สายไ | F66: LKT. 2026-05 -PL880 | G66: 656600 | H66: 45962 | I66: 702562 | J66: 📋 ติดตาม | K66: — | L66: กลาง | M66: — | N66: 📧 ส่ง Email
A67: 63 | B67: PL641 | C67: บริษัท เอ็นเทค แมเนจเม้นท์ จำกัด (สำนักงานใหญ่) | D67: 2026-01 | E67: อื่นๆ | F67: LKT. 2026-01-PL641 | G67: 649600 | H67: 45472 | I67: 695072 | J67: 📋 ติดตาม | K67: — | L67: กลาง | M67: — | N67: 📧 ส่ง Email
A68: 64 | B68: PL780 | C68: ไชยวัฒน์ | D68: 2026-03 | E68: Post Top Pole 5M-T4-TR | F68: LKT. 2026-03 -PL780 | G68: 641410 | H68: 44898.7 | I68: 686308.7 | J68: 📋 ติดตาม | K68: — | L68: กลาง | M68: — | N68: 📧 ส่ง Email
A69: 65 | B69: PL806 | C69: วิหลี | D69: 2026-04 | E69: Pole With Bracket 6M-T4-TR | F69: LKT. 2026-04 -PL806 | G69: 631747.2 | H69: 44222.3 | I69: 675969.5 | J69: 📋 ติดตาม | K69: — | L69: กลาง | M69: — | N69: 📧 ส่ง Email
A70: 66 | B70: PL683 | C70: ศิรประภาก่อสร้าง | D70: 2026-02 | E70: Pole With Bracket 9M-T4-TR | F70: LKT. 2026-01 -PL683 | G70: 626857 | H70: 43879.99 | I70: 670736.99 | J70: 📋 ติดตาม | K70: — | L70: กลาง | M70: — | N70: 📧 ส่ง Email
A71: 67 | B71: PL943 | C71: บมจ.เมืองไทยประกันชีวิต | D71: 2026-06 | E71: High Mast 15M+Motor (4 ต้น)+ค่ | F71: LKT. 2026-06 -PL943 | G71: 610599 | H71: 42741.93 | I71: 653340.93 | J71: 📋 ติดตาม | K71: — | L71: กลาง | M71: — | N71: 📧 ส่ง Email
A72: 68 | B72: PL697 | C72: อาริยะ กรุ๊ป | D72: 2026-02 | E72: High mast Pole 20 M วงแหวน 6 โ | F72: LKT. 2026-02 -PL697 | G72: 601994.4 | H72: 42139.61 | I72: 644134.01 | J72: 📋 ติดตาม | K72: — | L72: กลาง | M72: — | N72: 📧 ส่ง Email
A73: 69 | B73: PL824 | C73: บ.เจมินี เทค กรมท่ากระบี่ | D73: 2026-04 | E73: Pole With Bracket 9M-T4-TR | F73: LKT. 2026-04 -PL824 | G73: 589950 | H73: 41296.5 | I73: 631246.5 | J73: 📋 ติดตาม | K73: — | L73: กลาง | M73: DOA | N73: 📧 ส่ง Email
... A103: 99 | B103: PL612 | C103: สมบูรณ์อิเล็คทริค | D103: 2026-01 | E103: BTFL-ZC03-400W/LED FLOODLIGHT | F103: LKT. 2026-01 -PL612 | G103: 453936 | H103: 31775.52 | I103: 485711.52 | J103: 📋 ติดตาม | K103: — | L103: กลาง | M103: — | N103: 📧 ส่ง Email
A104: 100 | B104: PL713 | C104: แซทคอมส์ | D104: 2026-02 | E104: อื่นๆ | G104: 453152 | H104: 31720.64 | I104: 484872.64 | J104: 📋 ติดตาม | K104: — | L104: กลาง | M104: — | N104: 📧 ส่ง Email
A105: 101 | B105: PL636 | C105: ท็อปเบสท์ แมนูแฟคเจอริ่ง | D105: 2026-01 | E105: Pole With Bracket 6M-T4-TR | F105: LKT. 2026-01 -PL636 | G105: 444072.3 | H105: 31085.06 | I105: 475157.36 | J105: 📋 ติดตาม | K105: — | L105: กลาง | M105: — | N105: 📧 ส่ง Email
A106: 102 | B106: PL685 | C106: เทอร์ม เอ็นจิเนียริ่ง | D106: 2026-02 | E106: เสาสายลอฟา 30M | F106: LKT. 2026-02 -PL685 | G106: 441196 | H106: 30883.72 | I106: 472079.72 | J106: 📋 ติดตาม | K106: — | L106: กลาง | M106: — | N106: 📧 ส่ง Email
A107: 103 | B107: PL923 | C107: เดลต้า พลัส เอ็นจิเนียริ่ง | D107: 2026-06 | E107: High Mast 10M 6t+Support 2ชั้น | F107: LKT. 2026-06-PL923 | G107: 440200 | H107: 30814 | I107: 471014 | J107: 📋 ติดตาม | K107: — | L107: กลาง | M107: DOA | N107: 📧 ส่ง Email
A108: 104 | B108: PL855 | C108: บ.นิวสตาร์ | D108: 2026-05 | E108: High Mast Pole 10 M + วงแหวน 6 | F108: LKT. 2026-05-PL855 | G108: 434532 | H108: 30417.24 | I108: 464949.24 | J108: 📋 ติดตาม | K108: — | L108: กลาง | M108: — | N108: 📧 ส่ง Email
A109: 105 | B109: PL634 | C109: ไอซีซี | D109: 2026-01 | E109: High mast Pole 25 M วงแหวน 8 โ | F109: LKT. 2026-01 -PL634 | G109: 432140.8 | H109: 30249.86 | I109: 462390.66 | J109: 📋 ติดตาม | K109: — | L109: กลาง | M109: — | N109: 📧 ส่ง Email
...
